<?xml version="1.0" ?>
<sdf version="1.8">
  <model name='vehicle_blue'>
    <pose>0 0 0 0 0 0</pose>      <!--the pose is relative to the world by default-->

    <!-- #region links -->
    <link name='chassis'>
      <pose relative_to='__model__'>0.5 0 0.4 0 0 0</pose>
      <inertial>          <!--inertial properties of the link mass, inertia matix-->
        <mass>1.14395</mass>
        <inertia>
          <ixx>0.126164</ixx>
          <ixy>0</ixy>
          <ixz>0</ixz>
          <iyy>0.416519</iyy>
          <iyz>0</iyz>
          <izz>0.481014</izz>
        </inertia>
      </inertial>
      <visual name='visual'>
        <geometry>
          <box>
            <size>2.0 1.0 0.5</size>              <!--question: this size is in meter-->
          </box>
        </geometry>
        <!--let's add color to our link-->
        <material>
          <ambient>0.0 0.0 1.0 1</ambient>
          <diffuse>0.0 0.0 1.0 1</diffuse>
          <specular>0.0 0.0 1.0 1</specular>
        </material>
      </visual>
      <collision name='collision'>          <!--todo: describe why we need the collision-->
        <geometry>
          <box>
            <size>2.0 1.0 0.5</size>
          </box>
        </geometry>
      </collision>
    </link>

    <!--let's build the left wheel-->
    <link name='left_wheel'>
      <pose relative_to="chassis">-0.5 0.6 0 -1.5707 0 0</pose>        <!--angles are in radian-->
      <inertial>
        <mass>2</mass>
        <inertia>
          <ixx>0.145833</ixx>
          <ixy>0</ixy>
          <ixz>0</ixz>
          <iyy>0.145833</iyy>
          <iyz>0</iyz>
          <izz>0.125</izz>
        </inertia>
      </inertial>
      <visual name='visual'>
        <geometry>
          <cylinder>
            <radius>0.4</radius>
            <length>0.2</length>
          </cylinder>
        </geometry>
        <material>
          <ambient>1.0 0.0 0.0 1</ambient>
          <diffuse>1.0 0.0 0.0 1</diffuse>
          <specular>1.0 0.0 0.0 1</specular>
        </material>
      </visual>
      <collision name='collision'>
        <geometry>
          <cylinder>
            <radius>0.4</radius>
            <length>0.2</length>
          </cylinder>
        </geometry>
      </collision>
    </link>

    <!--copy and paste for right wheel but change position-->
    <link name='right_wheel'>
      <pose relative_to="chassis">-0.5 -0.6 0 -1.5707 0 0</pose>        <!--angles are in radian-->
      <inertial>
        <mass>1</mass>
        <inertia>
          <ixx>0.145833</ixx>
          <ixy>0</ixy>
          <ixz>0</ixz>
          <iyy>0.145833</iyy>
          <iyz>0</iyz>
          <izz>0.125</izz>
        </inertia>
      </inertial>
      <visual name='visual'>
        <geometry>
          <cylinder>
            <radius>0.4</radius>
            <length>0.2</length>
          </cylinder>
        </geometry>
        <material>
          <ambient>1.0 0.0 0.0 1</ambient>
          <diffuse>1.0 0.0 0.0 1</diffuse>
          <specular>1.0 0.0 0.0 1</specular>
        </material>
      </visual>
      <collision name='collision'>
        <geometry>
          <cylinder>
            <radius>0.4</radius>
            <length>0.2</length>
          </cylinder>
        </geometry>
      </collision>
    </link>

    <frame name="camera_frame" attached_to='chassis'>
      <pose>-0.8 0 1.5 0 0 0</pose>
    </frame>

    <link name="camera_link">
      <pose relative_to='camera_frame'>0 0 0 0 0 0</pose>
      <inertial>
        <mass>0.1</mass>
        <inertia>
          <ixx>0.000166667</ixx>
          <iyy>0.000166667</iyy>
          <izz>0.000166667</izz>
        </inertia>
      </inertial>
      <collision name="collision">
        <geometry>
          <box>
            <size>0.1 0.1 0.1</size>
          </box>
        </geometry>
      </collision>
      <visual name="visual">
        <geometry>
          <box>
            <size>0.1 0.1 0.1</size>
          </box>
        </geometry>
      </visual>
      <sensor name="camera" type="camera">
        <camera>
          <horizontal_fov>1.047</horizontal_fov>
          <image>
            <width>320</width>
            <height>240</height>
          </image>
          <clip>
            <near>0.1</near>
            <far>100</far>
          </clip>
        </camera>
        <always_on>1</always_on>
        <update_rate>30</update_rate>
        <visualize>true</visualize>
        <topic>camera</topic>
      </sensor>
    </link>

    <joint name='camera_joint' type='fixed'>
      <parent>chassis</parent>
      <child>camera_link</child>
    </joint>

    <frame name="caster_frame" attached_to='chassis'>
      <pose>0.8 0 -0.2 0 0 0</pose>
    </frame>

    <!--caster wheel-->
    <link name='caster'>
      <pose relative_to='caster_frame'/>
      <inertial>
        <mass>1</mass>
        <inertia>
          <ixx>0.1</ixx>
          <ixy>0</ixy>
          <ixz>0</ixz>
          <iyy>0.1</iyy>
          <iyz>0</iyz>
          <izz>0.1</izz>
        </inertia>
      </inertial>
      <visual name='visual'>
        <geometry>
          <sphere>
            <radius>0.2</radius>
          </sphere>
        </geometry>
        <material>
          <ambient>0.0 1 0.0 1</ambient>
          <diffuse>0.0 1 0.0 1</diffuse>
          <specular>0.0 1 0.0 1</specular>
        </material>
      </visual>
      <collision name='collision'>
        <geometry>
          <sphere>
            <radius>0.2</radius>
          </sphere>
        </geometry>
      </collision>
    </link>
    <!-- #endregion links -->
    <!-- #region joints -->
    <!--connecting these links together using joints-->
    <joint name='left_wheel_joint' type='revolute'>        <!--continous joint is not supported yet-->
      <pose relative_to='left_wheel'/>
      <parent>chassis</parent>
      <child>left_wheel</child>
      <axis>
        <xyz expressed_in='__model__'>0 1 0</xyz>          <!--can be defined as any frame or even arbitrary frames-->
        <limit>
          <lower>-1.79769e+308</lower>            <!--negative infinity-->
          <upper>1.79769e+308</upper>            <!--positive infinity-->
        </limit>
      </axis>
    </joint>

    <joint name='right_wheel_joint' type='revolute'>
      <pose relative_to='right_wheel'/>
      <parent>chassis</parent>
      <child>right_wheel</child>
      <axis>
        <xyz expressed_in='__model__'>0 1 0</xyz>
        <limit>
          <lower>-1.79769e+308</lower>            <!--negative infinity-->
          <upper>1.79769e+308</upper>            <!--positive infinity-->
        </limit>
      </axis>
    </joint>

    <!--different type of joints ball joint-->      <!--defult value is the child-->
    <joint name='caster_wheel' type='ball'>
      <parent>chassis</parent>
      <child>caster</child>
      <axis>
        <xyz expressed_in='__model__'>0 1 0</xyz>
        <limit>
          <lower>-1.79769e+308</lower>            <!--negative infinity-->
          <upper>1.79769e+308</upper>            <!--positive infinity-->
        </limit>
      </axis>
    </joint>
    <!-- #endregion joints-->

    <!--diff drive plugin-->
    <plugin filename="libignition-gazebo-diff-drive-system.so" name="ignition::gazebo::systems::DiffDrive">
      <left_joint>left_wheel_joint</left_joint>
      <right_joint>right_wheel_joint</right_joint>
      <wheel_separation>1.2</wheel_separation>
      <wheel_radius>0.4</wheel_radius>
      <odom_publish_frequency>1</odom_publish_frequency>
      <frame_id>odom</frame_id>
			<child_frame_id>chassis</child_frame_id>
    </plugin>

    <plugin
      filename="libignition-gazebo-joint-state-publisher-system.so"
      name="ignition::gazebo::systems::JointStatePublisher">
    </plugin>
  </model>
</sdf>
